Workbook

Sheet 가정
A1: 방치형 타워디펜스 — 경제 시뮬레이션
A2: 노란색 셀만 수정하세요. 나머지 시트는 전부 자동 계산됩니다.
A4: 전투 · 적
A5: 기본 적 체력 (웨이브 1, 개체당) | B5: 10 | C5: 웨이브 1 적 한 마리의 체력. 기준값이라 값 자체는 무의미
A6: 적 체력 증가율 (웨이브당) | B6: 1.09 | C6: 핵심 레버. 1.08~1.10 권장. 높일수록 벽이 빨리 옴
A7: 웨이브당 적 수 | B7: 10 | C7: 고정. 늘리면 전투가 길어지고 발열이 증가
A8: 재화 · 코인
A9: 기본 코인 보상 (개체당) | B9: 2 | C9: 웨이브 1에서 적 1마리 처치 시 코인
A10: 코인 증가율 (웨이브당) | B10: 1.075 | C10: 반드시 체력 증가율보다 낮게. 이 격차가 '벽'을 만듦
A11: 타워 · 업그레이드
A12: 기본 DPS (업그레이드 0레벨) | B12: 5 | C12: 초당 피해량 시작값
A13: 업그레이드 기본 비용 (1레벨) | B13: 10 | C13: 첫 업그레이드 가격
A14: 업그레이드 비용 증가율 | B14: 1.12 | C14: 레벨당 비용 배수. 1.10~1.15 권장
A15: 업그레이드당 DPS 증가 (고정값) | B15: 3 | C15: 선형 증가. 비용은 지수, 파워는 선형 = 방치형의 기본 공식
A16: 목표 · 판정 기준
A17: 웨이브 소요시간 하한 (초) | B17: 5 | C17: 이보다 빠르면 성장 실감이 안 남
A18: 웨이브 소요시간 상한 (초) | B18: 45 | C18: 이보다 느리면 지루함 — 이탈 구간
A19: 환생(프레스티지) 목표 웨이브 | B19: 50 | C19: 유저가 처음 벽에 부딪히길 원하는 지점
A24: 튜닝 순서
A25: 1. '웨이브시뮬레이션' 시트 J열이 '적정'으로 채워지는 구간을 최대한 넓힌다
A26: 2. 환생 목표 웨이브에서 웨이브 시간이 상한을 넘도록 (= 벽이 여기서 생기도록) 조정
A27: 3. 그 웨이브까지의 누적 시간(I열)이 첫 판 목표 길이가 된다
A28: 4. 조정은 '적 체력 증가율'과 '코인 증가율'의 격차로만 한다. 나머지는 건드리지 말 것
A31: 환생 메타 (2층)
A32: 도달 웨이브 계수 (W0) | B32: 37.7 | C32: 회차 1의 도달 웨이브를 결정
A33: 도달 웨이브 지수 | B33: 0.269 | C33: 높일수록 회차마다 더 멀리 감 = 커브가 짧아짐
A34: 티어 배수 (승천 1회당) | B34: 2.5 | C34: 2층 환생. 선형 코어만으로는 장기 곡선을 못 버팀
A35: 티어업 시 코어 유지율 | B35: 0.15 | C35: 85%를 소각. 리셋이 없으면 티어 배수가 폭주
A36: 코어 획득 지수 | B36: 1.6 | C36: 획득 코어 = (도달웨이브/10)^지수
A37: 코어당 공격 증가 | B37: 0.02 | C37: 코어 1개당 공격 배수 증가분
A38: 코어당 코인 증가 | B38: 0.015 | C38: 공격보다 낮게 유지
A39: 일일 런 수 (평균 유저) | B39: 3 | C39: 런 1회 약 10분 기준
A41: 티어 게이트 (도달 웨이브) | C41: 이 웨이브에 도달하면 승천 가능. 간격이 점점 벌어지는 것이 정상
A42: 티어 2 개방 | B42: 50 | C42: C# 검증 결과 60→50 수정. 60이면 3~5회차 여유가 0.91로 진행 불가
A43: 티어 3 개방 | B43: 80
A44: 티어 4 개방 | B44: 100
A45: 티어 5 개방 | B45: 125
A46: 티어 6 개방 | B46: 150
A47: 티어 7 개방 | B47: 180
A48: 티어 8 개방 | B48: 215
...

Sheet 웨이브시뮬레이션
A1: 웨이브 | B1: 적 체력(개체) | C1: 웨이브 총체력 | D1: 웨이브 코인 | E1: 누적 코인 | F1: 업그레이드 Lv | G1: DPS | H1: 웨이브 시간(초) | I1: 누적 시간(분) | J1: 판정
A2: 1 | B2: =가정!$B$5*가정!$B$6^(A2-1) -> 10 | C2: =B2*가정!$B$7 -> 100 | D2: =가정!$B$9*가정!$B$10^(A2-1)*가정!$B$7 -> 20 | E2: =D2 -> 20 | F2: =INT(LOG(E2*(가정!$B$14-1)/가정!$B$13+1)/LOG(가정!$B$14)) -> 1 | G2: =가정!$B$12+F2*가정!$B$15 -> 8 | H2: =C2/G2 -> 12.5 | I2: =H2/60 -> 0.20833333 | J2: =IF(H2<가정!$B$17,"빠름",IF(H2>가정!$B$18,"느림","적정")) -> 적정
A3: 2 | B3: =가정!$B$5*가정!$B$6^(A3-1) -> 10.9 | C3: =B3*가정!$B$7 -> 109 | D3: =가정!$B$9*가정!$B$10^(A3-1)*가정!$B$7 -> 21.5 | E3: =E2+D3 -> 41.5 | F3: =INT(LOG(E3*(가정!$B$14-1)/가정!$B$13+1)/LOG(가정!$B$14)) -> 3 | G3: =가정!$B$12+F3*가정!$B$15 -> 14 | H3: =C3/G3 -> 7.7857143 | I3: =I2+H3/60 -> 0.33809524 | J3: =IF(H3<가정!$B$17,"빠름",IF(H3>가정!$B$18,"느림","적정")) -> 적정
A4: 3 | B4: =가정!$B$5*가정!$B$6^(A4-1) -> 11.881 | C4: =B4*가정!$B$7 -> 118.81 | D4: =가정!$B$9*가정!$B$10^(A4-1)*가정!$B$7 -> 23.1125 | E4: =E3+D4 -> 64.6125 | F4: =INT(LOG(E4*(가정!$B$14-1)/가정!$B$13+1)/LOG(가정!$B$14)) -> 5 | G4: =가정!$B$12+F4*가정!$B$15 -> 20 | H4: =C4/G4 -> 5.9405 | I4: =I3+H4/60 -> 0.43710357 | J4: =IF(H4<가정!$B$17,"빠름",IF(H4>가정!$B$18,"느림","적정")) -> 적정
A5: 4 | B5: =가정!$B$5*가정!$B$6^(A5-1) -> 12.95029 | C5: =B5*가정!$B$7 -> 129.5029 | D5: =가정!$B$9*가정!$B$10^(A5-1)*가정!$B$7 -> 24.845938 | E5: =E4+D5 -> 89.458438 | F5: =INT(LOG(E5*(가정!$B$14-1)/가정!$B$13+1)/LOG(가정!$B$14)) -> 6 | G5: =가정!$B$12+F5*가정!$B$15 -> 23 | H5: =C5/G5 -> 5.6305609 | I5: =I4+H5/60 -> 0.53094625 | J5: =IF(H5<가정!$B$17,"빠름",IF(H5>가정!$B$18,"느림","적정")) -> 적정
A6: 5 | B6: =가정!$B$5*가정!$B$6^(A6-1) -> 14.115816 | C6: =B6*가정!$B$7 -> 141.15816 | D6: =가정!$B$9*가정!$B$10^(A6-1)*가정!$B$7 -> 26.709383 | E6: =E5+D6 -> 116.16782 | F6: =INT(LOG(E6*(가정!$B$14-1)/가정!$B$13+1)/LOG(가정!$B$14)) -> 7 | G6: =가정!$B$12+F6*가정!$B$15 -> 26 | H6: =C6/G6 -> 5.42916 | I6: =I5+H6/60 -> 0.62143225 | J6: =IF(H6<가정!$B$17,"빠름",IF(H6>가정!$B$18,"느림","적정")) -> 적정
A7: 6 | B7: =가정!$B$5*가정!$B$6^(A7-1) -> 15.38624 | C7: =B7*가정!$B$7 -> 153.8624 | D7: =가정!$B$9*가정!$B$10^(A7-1)*가정!$B$7 -> 28.712587 | E7: =E6+D7 -> 144.88041 | F7: =INT(LOG(E7*(가정!$B$14-1)/가정!$B$13+1)/LOG(가정!$B$14)) -> 8 | G7: =가정!$B$12+F7*가정!$B$15 -> 29 | H7: =C7/G7 -> 5.3055998 | I7: =I6+H7/60 -> 0.70985892 | J7: =IF(H7<가정!$B$17,"빠름",IF(H7>가정!$B$18,"느림","적정")) -> 적정
A8: 7 | B8: =가정!$B$5*가정!$B$6^(A8-1) -> 16.771001 | C8: =B8*가정!$B$7 -> 167.71001 | D8: =가정!$B$9*가정!$B$10^(A8-1)*가정!$B$7 -> 30.866031 | E8: =E7+D8 -> 175.74644 | F8: =INT(LOG(E8*(가정!$B$14-1)/가정!$B$13+1)/LOG(가정!$B$14)) -> 10 | G8: =가정!$B$12+F8*가정!$B$15 -> 35 | H8: =C8/G8 -> 4.7917146 | I8: =I7+H8/60 -> 0.78972083 | J8: =IF(H8<가정!$B$17,"빠름",IF(H8>가정!$B$18,"느림","적정")) -> 빠름
A9: 8 | B9: =가정!$B$5*가정!$B$6^(A9-1) -> 18.280391 | C9: =B9*가정!$B$7 -> 182.80391 | D9: =가정!$B$9*가정!$B$10^(A9-1)*가정!$B$7 -> 33.180983 | E9: =E8+D9 -> 208.92742 | F9: =INT(LOG(E9*(가정!$B$14-1)/가정!$B$13+1)/LOG(가정!$B$14)) -> 11 | G9: =가정!$B$12+F9*가정!$B$15 -> 38 | H9: =C9/G9 -> 4.8106293 | I9: =I8+H9/60 -> 0.86989798 | J9: =IF(H9<가정!$B$17,"빠름",IF(H9>가정!$B$18,"느림","적정")) -> 빠름
A10: 9 | B10: =가정!$B$5*가정!$B$6^(A10-1) -> 19.925626 | C10: =B10*가정!$B$7 -> 199.25626 | D10: =가정!$B$9*가정!$B$10^(A10-1)*가정!$B$7 -> 35.669557 | E10: =E9+D10 -> 244.59698 | F10: =INT(LOG(E10*(가정!$B$14-1)/가정!$B$13+1)/LOG(가정!$B$14)) -> 12 | G10: =가정!$B$12+F10*가정!$B$15 -> 41 | H10: =C10/G10 -> 4.8599089 | I10: =I9+H10/60 -> 0.95089646 | J10: =IF(H10<가정!$B$17,"빠름",IF(H10>가정!$B$18,"느림","적정")) -> 빠름
A11: 10 | B11: =가정!$B$5*가정!$B$6^(A11-1) -> 21.718933 | C11: =B11*가정!$B$7 -> 217.18933 | D11: =가정!$B$9*가정!$B$10^(A11-1)*가정!$B$7 -> 38.344773 | E11: =E10+D11 -> 282.94175 | F11: =INT(LOG(E11*(가정!$B$14-1)/가정!$B$13+1)/LOG(가정!$B$14)) -> 13 | G11: =가정!$B$12+F11*가정!$B$15 -> 44 | H11: =C11/G11 -> 4.9361211 | I11: =I10+H11/60 -> 1.0331651 | J11: =IF(H11<가정!$B$17,"빠름",IF(H11>가정!$B$18,"느림","적정")) -> 빠름
A12: 11 | B12: =가정!$B$5*가정!$B$6^(A12-1) -> 23.673637 | C12: =B12*가정!$B$7 -> 236.73637 | D12: =가정!$B$9*가정!$B$10^(A12-1)*가정!$B$7 -> 41.220631 | E12: =E11+D12 -> 324.16238 | F12: =INT(LOG(E12*(가정!$B$14-1)/가정!$B$13+1)/LOG(가정!$B$14)) -> 14 | G12: =가정!$B$12+F12*가정!$B$15 -> 47 | H12: =C12/G12 -> 5.036944 | I12: =I11+H12/60 -> 1.1171142 | J12: =IF(H12<가정!$B$17,"빠름",IF(H12>가정!$B$18,"느림","적정")) -> 적정
A13: 12 | B13: =가정!$B$5*가정!$B$6^(A13-1) -> 25.804264 | C13: =B13*가정!$B$7 -> 258.04264 | D13: =가정!$B$9*가정!$B$10^(A13-1)*가정!$B$7 -> 44.312179 | E13: =E12+D13 -> 368.47456 | F13: =INT(LOG(E13*(가정!$B$14-1)/가정!$B$13+1)/LOG(가정!$B$14)) -> 14 | G13: =가정!$B$12+F13*가정!$B$15 -> 47 | H13: =C13/G13 -> 5.4902689 | I13: =I12+H13/60 -> 1.2086187 | J13: =IF(H13<가정!$B$17,"빠름",IF(H13>가정!$B$18,"느림","적정")) -> 적정
A14: 13 | B14: =가정!$B$5*가정!$B$6^(A14-1) -> 28.126648 | C14: =B14*가정!$B$7 -> 281.26648 | D14: =가정!$B$9*가정!$B$10^(A14-1)*가정!$B$7 -> 47.635592 | E14: =E13+D14 -> 416.11015 | F14: =INT(LOG(E14*(가정!$B$14-1)/가정!$B$13+1)/LOG(가정!$B$14)) -> 15 | G14: =가정!$B$12+F14*가정!$B$15 -> 50 | H14: =C14/G14 -> 5.6253296 | I14: =I13+H14/60 -> 1.3023742 | J14: =IF(H14<가정!$B$17,"빠름",IF(H14>가정!$B$18,"느림","적정")) -> 적정
... A101: 100 | B101: =가정!$B$5*가정!$B$6^(A101-1) -> 50725.145 | C101: =B101*가정!$B$7 -> 507251.45 | D101: =가정!$B$9*가정!$B$10^(A101-1)*가정!$B$7 -> 25731.669 | E101: =E100+D101 -> 368553.92 | F101: =INT(LOG(E101*(가정!$B$14-1)/가정!$B$13+1)/LOG(가정!$B$14)) -> 74 | G101: =가정!$B$12+F101*가정!$B$15 -> 227 | H101: =C101/G101 -> 2234.5879 | I101: =I100+H101/60 -> 509.541 | J101: =IF(H101<가정!$B$17,"빠름",IF(H101>가정!$B$18,"느림","적정")) -> 느림

Sheet 업그레이드비용
A1: 레벨 | B1: 해당 레벨 비용 | C1: 누적 비용 | D1: 누적 DPS | E1: 코인당 DPS 효율
A2: 1 | B2: =가정!$B$13*가정!$B$14^(A2-1) -> 10 | C2: =B2 -> 10 | D2: =가정!$B$12+A2*가정!$B$15 -> 8 | E2: =D2/C2 -> 0.8
A3: 2 | B3: =가정!$B$13*가정!$B$14^(A3-1) -> 11.2 | C3: =C2+B3 -> 21.2 | D3: =가정!$B$12+A3*가정!$B$15 -> 11 | E3: =D3/C3 -> 0.51886792
A4: 3 | B4: =가정!$B$13*가정!$B$14^(A4-1) -> 12.544 | C4: =C3+B4 -> 33.744 | D4: =가정!$B$12+A4*가정!$B$15 -> 14 | E4: =D4/C4 -> 0.41488857
A5: 4 | B5: =가정!$B$13*가정!$B$14^(A5-1) -> 14.04928 | C5: =C4+B5 -> 47.79328 | D5: =가정!$B$12+A5*가정!$B$15 -> 17 | E5: =D5/C5 -> 0.35569854
A6: 5 | B6: =가정!$B$13*가정!$B$14^(A6-1) -> 15.735194 | C6: =C5+B6 -> 63.528474 | D6: =가정!$B$12+A6*가정!$B$15 -> 20 | E6: =D6/C6 -> 0.31481946
A7: 6 | B7: =가정!$B$13*가정!$B$14^(A7-1) -> 17.623417 | C7: =C6+B7 -> 81.15189 | D7: =가정!$B$12+A7*가정!$B$15 -> 23 | E7: =D7/C7 -> 0.28341915
A8: 7 | B8: =가정!$B$13*가정!$B$14^(A8-1) -> 19.738227 | C8: =C7+B8 -> 100.89012 | D8: =가정!$B$12+A8*가정!$B$15 -> 26 | E8: =D8/C8 -> 0.25770611
A9: 8 | B9: =가정!$B$13*가정!$B$14^(A9-1) -> 22.106814 | C9: =C8+B9 -> 122.99693 | D9: =가정!$B$12+A9*가정!$B$15 -> 29 | E9: =D9/C9 -> 0.23577824
A10: 9 | B10: =가정!$B$13*가정!$B$14^(A10-1) -> 24.759632 | C10: =C9+B10 -> 147.75656 | D10: =가정!$B$12+A10*가정!$B$15 -> 32 | E10: =D10/C10 -> 0.21657244
A11: 10 | B11: =가정!$B$13*가정!$B$14^(A11-1) -> 27.730788 | C11: =C10+B11 -> 175.48735 | D11: =가정!$B$12+A11*가정!$B$15 -> 35 | E11: =D11/C11 -> 0.19944457
A12: 11 | B12: =가정!$B$13*가정!$B$14^(A12-1) -> 31.058482 | C12: =C11+B12 -> 206.54583 | D12: =가정!$B$12+A12*가정!$B$15 -> 38 | E12: =D12/C12 -> 0.18397854
A13: 12 | B13: =가정!$B$13*가정!$B$14^(A13-1) -> 34.7855 | C13: =C12+B13 -> 241.33133 | D13: =가정!$B$12+A13*가정!$B$15 -> 41 | E13: =D13/C13 -> 0.16989091
A14: 13 | B14: =가정!$B$13*가정!$B$14^(A14-1) -> 38.95976 | C14: =C13+B14 -> 280.29109 | D14: =가정!$B$12+A14*가정!$B$15 -> 44 | E14: =D14/C14 -> 0.15697966
... A101: 100 | B101: =가정!$B$13*가정!$B$14^(A101-1) -> 745734.52 | C101: =C100+B101 -> 6960105.5 | D101: =가정!$B$12+A101*가정!$B$15 -> 305 | E101: =D101/C101 -> 4.3821175e-05
A103: 코인당 DPS 효율이 계속 떨어지는 것이 정상입니다. 이 하락이 환생의 동기를 만듭니다.

Sheet 수익모델
A1: 수익 모델 — ARPDAU / LTV / 목표 CPI
A2: 노란색 셀만 수정. 리워드 광고 중심 + 전면광고는 라운드 종료 시 최소한만.
A4: 인게임 행동 (목표치)
A5: 일 세션 수 / DAU | B5: 6 | C5: 3장 목표: 6회
A6: 세션당 리워드 광고 시청 | B6: 1.2 | C6: 오프라인보상 + 배속 + 부활 중 평균
A7: 리워드 광고 eCPM ($) | B7: 18 | C7: 북미 기준. 신흥국은 3~6달러
A8: 전면 광고 노출 / 세션 | B8: 0.3 | C8: 라운드 종료 후에만. 오프라인 보상 등 핵심 동선에는 절대 금지
A9: 전면 광고 eCPM ($) | B9: 9 | C9: 리워드보다 낮음
A11: 광고 수익
A12: 일 리워드 광고 노출 / DAU | B12: =B5*B6 -> 7.2
A13: 일 전면 광고 노출 / DAU | B13: =B5*B8 -> 1.8
A14: 광고 ARPDAU ($) | B14: =B12*B7/1000+B13*B9/1000 -> 0.1458 | C14: 유저 1명이 하루에 만드는 광고 수익
A16: 인앱 결제
A17: 일 결제 전환율 (DAU 대비) | B17: 0.018 | C17: 일반 캐주얼은 1~2%. 방치형은 메타가 깊어 다소 높게 나옴
A18: ARPPU — 결제 1건 평균 ($) | B18: 12.5 | C18: 주간 구독 + 광고제거 + 젬팩 혼합 가정
A19: IAP ARPDAU ($) | B19: =B17*B18 -> 0.225
A21: 종합
A22: 총 ARPDAU ($) | B22: =B14+B19 -> 0.3708
A23: IAP 비중 | B23: =IFERROR(B19/B22,0) -> 0.60679612 | C23: 목표 55~60%
A24: 광고 비중 | B24: =IFERROR(B14/B22,0) -> 0.39320388 | C24: 목표 40~45%
A25: 목표(58%) 대비 IAP 갭 | B25: =B23-0.58 -> 0.026796117 | C25: 음수면 광고 의존이 과함 — IAP 설계를 보강할 것
A26: LTV · UA
A27: 평균 유저 수명 (일) | B27: 45 | C27: D30 8% 가정 시 대략치
A28: LTV ($) | B28: =B22*B27 -> 16.686
A29: 목표 ROAS (배) | B29: 1.4 | C29: 1.0 미만이면 광고 태울수록 손해
A30: 감당 가능 최대 CPI ($) | B30: =IFERROR(B28/B29,0) -> 11.918571 | C30: 실제 CPI가 이보다 높으면 스케일 불가
A32: 규모 시나리오
A33: 소규모 — DAU 10,000 | B33: 10000 | C33: =B33*$B$22*30 -> 111240 | D33: 월 매출
A34: 중간 — DAU 50,000 | B34: 50000 | C34: =B34*$B$22*30 -> 556200 | D34: 월 매출
A35: 성공 — DAU 200,000 | B35: 200000 | C35: =B35*$B$22*30 -> 2224800 | D35: 월 매출
A37: 주의 — 위 수치는 전부 목표 가정입니다. 소프트런치 실측값으로 반드시 교체하세요.

Sheet 환생메타
A1: 회차 | B1: 도달 웨이브 | C1: 티어 | D1: 티어 배수 | E1: 획득 코어 | F1: 누적 코어 | G1: 공격 배수 | H1: 코인 배수 | I1: 필요 DPS | J1: 실제 DPS | K1: 여유 | L1: 누적 일수 | M1: 판정
A2: 1 | B2: =ROUND(가정!$B$32*(A2+1)^가정!$B$33,0) -> 45 | C2: 1 | D2: =가정!$B$34^(C2-1) -> 1 | E2: =(B2/10)^가정!$B$36 -> 11.095325 | F2: =E2 -> 11.095325 | G2: =(1+F2*가정!$B$37)*D2 -> 1.2219065 | H2: =(1+F2*가정!$B$38)*D2^0.6 -> 1.1664299 | I2: =가정!$B$5*가정!$B$7*가정!$B$6^(B2-1)/가정!$B$18 -> 98.526577 | J2: =(가정!$B$12+가정!$B$15*(LOG(가정!$B$9*가정!$B$7*H2*가정!$B$10^B2/(가정!$B$10-1)*(가정!$B$14-1)/가정!$B$13)/LOG(가정!$B$14)))*G2 -> 153.97978 | K2: =IFERROR(J2/I2,0) -> 1.5628248 | L2: =A2/가정!$B$39 -> 0.33333333 | M2: =IF(K2<1,"미달",IF(K2>4,"과잉","적정")) -> 적정
A3: 2 | B3: =ROUND(가정!$B$32*(A3+1)^가정!$B$33,0) -> 51 | C3: =IF(B3>=IFERROR(INDEX(가정!$B$42:$B$50,C2),1000000),C2+1,C2) -> 2 | D3: =가정!$B$34^(C3-1) -> 2.5 | E3: =(B3/10)^가정!$B$36 -> 13.555398 | F3: =IF(C3>C2,(F2+E3)*가정!$B$35,F2+E3) -> 3.6976085 | G3: =(1+F3*가정!$B$37)*D3 -> 2.6848804 | H3: =(1+F3*가정!$B$38)*D3^0.6 -> 1.8289738 | I3: =가정!$B$5*가정!$B$7*가정!$B$6^(B3-1)/가정!$B$18 -> 165.23893 | J3: =(가정!$B$12+가정!$B$15*(LOG(가정!$B$9*가정!$B$7*H3*가정!$B$10^B3/(가정!$B$10-1)*(가정!$B$14-1)/가정!$B$13)/LOG(가정!$B$14)))*G3 -> 401.14759 | K3: =IFERROR(J3/I3,0) -> 2.427682 | L3: =A3/가정!$B$39 -> 0.66666667 | M3: =IF(K3<1,"미달",IF(K3>4,"과잉","적정")) -> 적정
A4: 3 | B4: =ROUND(가정!$B$32*(A4+1)^가정!$B$33,0) -> 55 | C4: =IF(B4>=IFERROR(INDEX(가정!$B$42:$B$50,C3),1000000),C3+1,C3) -> 2 | D4: =가정!$B$34^(C4-1) -> 2.5 | E4: =(B4/10)^가정!$B$36 -> 15.296086 | F4: =IF(C4>C3,(F3+E4)*가정!$B$35,F3+E4) -> 18.993694 | G4: =(1+F4*가정!$B$37)*D4 -> 3.4496847 | H4: =(1+F4*가정!$B$38)*D4^0.6 -> 2.2265639 | I4: =가정!$B$5*가정!$B$7*가정!$B$6^(B4-1)/가정!$B$18 -> 233.24824 | J4: =(가정!$B$12+가정!$B$15*(LOG(가정!$B$9*가정!$B$7*H4*가정!$B$10^B4/(가정!$B$10-1)*(가정!$B$14-1)/가정!$B$13)/LOG(가정!$B$14)))*G4 -> 559.79671 | K4: =IFERROR(J4/I4,0) -> 2.400004 | L4: =A4/가정!$B$39 -> 1 | M4: =IF(K4<1,"미달",IF(K4>4,"과잉","적정")) -> 적정
A5: 4 | B5: =ROUND(가정!$B$32*(A5+1)^가정!$B$33,0) -> 58 | C5: =IF(B5>=IFERROR(INDEX(가정!$B$42:$B$50,C4),1000000),C4+1,C4) -> 2 | D5: =가정!$B$34^(C5-1) -> 2.5 | E5: =(B5/10)^가정!$B$36 -> 16.652705 | F5: =IF(C5>C4,(F4+E5)*가정!$B$35,F4+E5) -> 35.646399 | G5: =(1+F5*가정!$B$37)*D5 -> 4.28232 | H5: =(1+F5*가정!$B$38)*D5^0.6 -> 2.6594165 | I5: =가정!$B$5*가정!$B$7*가정!$B$6^(B5-1)/가정!$B$18 -> 302.06323 | J5: =(가정!$B$12+가정!$B$15*(LOG(가정!$B$9*가정!$B$7*H5*가정!$B$10^B5/(가정!$B$10-1)*(가정!$B$14-1)/가정!$B$13)/LOG(가정!$B$14)))*G5 -> 739.64535 | K5: =IFERROR(J5/I5,0) -> 2.4486441 | L5: =A5/가정!$B$39 -> 1.3333333 | M5: =IF(K5<1,"미달",IF(K5>4,"과잉","적정")) -> 적정
A6: 5 | B6: =ROUND(가정!$B$32*(A6+1)^가정!$B$33,0) -> 61 | C6: =IF(B6>=IFERROR(INDEX(가정!$B$42:$B$50,C5),1000000),C5+1,C5) -> 2 | D6: =가정!$B$34^(C6-1) -> 2.5 | E6: =(B6/10)^가정!$B$36 -> 18.0521 | F6: =IF(C6>C5,(F5+E6)*가정!$B$35,F5+E6) -> 53.698499 | G6: =(1+F6*가정!$B$37)*D6 -> 5.184925 | H6: =(1+F6*가정!$B$38)*D6^0.6 -> 3.1286435 | I6: =가정!$B$5*가정!$B$7*가정!$B$6^(B6-1)/가정!$B$18 -> 391.18065 | J6: =(가정!$B$12+가정!$B$15*(LOG(가정!$B$9*가정!$B$7*H6*가정!$B$10^B6/(가정!$B$10-1)*(가정!$B$14-1)/가정!$B$13)/LOG(가정!$B$14)))*G6 -> 947.62548 | K6: =IFERROR(J6/I6,0) -> 2.4224754 | L6: =A6/가정!$B$39 -> 1.6666667 | M6: =IF(K6<1,"미달",IF(K6>4,"과잉","적정")) -> 적정
A7: 6 | B7: =ROUND(가정!$B$32*(A7+1)^가정!$B$33,0) -> 64 | C7: =IF(B7>=IFERROR(INDEX(가정!$B$42:$B$50,C6),1000000),C6+1,C6) -> 2 | D7: =가정!$B$34^(C7-1) -> 2.5 | E7: =(B7/10)^가정!$B$36 -> 19.493416 | F7: =IF(C7>C6,(F6+E7)*가정!$B$35,F6+E7) -> 73.191916 | G7: =(1+F7*가정!$B$37)*D7 -> 6.1595958 | H7: =(1+F7*가정!$B$38)*D7^0.6 -> 3.6353346 | I7: =가정!$B$5*가정!$B$7*가정!$B$6^(B7-1)/가정!$B$18 -> 506.59028 | J7: =(가정!$B$12+가정!$B$15*(LOG(가정!$B$9*가정!$B$7*H7*가정!$B$10^B7/(가정!$B$10-1)*(가정!$B$14-1)/가정!$B$13)/LOG(가정!$B$14)))*G7 -> 1185.6132 | K7: =IFERROR(J7/I7,0) -> 2.3403788 | L7: =A7/가정!$B$39 -> 2 | M7: =IF(K7<1,"미달",IF(K7>4,"과잉","적정")) -> 적정
A8: 7 | B8: =ROUND(가정!$B$32*(A8+1)^가정!$B$33,0) -> 66 | C8: =IF(B8>=IFERROR(INDEX(가정!$B$42:$B$50,C7),1000000),C7+1,C7) -> 2 | D8: =가정!$B$34^(C8-1) -> 2.5 | E8: =(B8/10)^가정!$B$36 -> 20.477187 | F8: =IF(C8>C7,(F7+E8)*가정!$B$35,F7+E8) -> 93.669103 | G8: =(1+F8*가정!$B$37)*D8 -> 7.1834551 | H8: =(1+F8*가정!$B$38)*D8^0.6 -> 4.1675967 | I8: =가정!$B$5*가정!$B$7*가정!$B$6^(B8-1)/가정!$B$18 -> 601.87992 | J8: =(가정!$B$12+가정!$B$15*(LOG(가정!$B$9*가정!$B$7*H8*가정!$B$10^B8/(가정!$B$10-1)*(가정!$B$14-1)/가정!$B$13)/LOG(가정!$B$14)))*G8 -> 1436.1756 | K8: =IFERROR(J8/I8,0) -> 2.3861497 | L8: =A8/가정!$B$39 -> 2.3333333 | M8: =IF(K8<1,"미달",IF(K8>4,"과잉","적정")) -> 적정
A9: 8 | B9: =ROUND(가정!$B$32*(A9+1)^가정!$B$33,0) -> 68 | C9: =IF(B9>=IFERROR(INDEX(가정!$B$42:$B$50,C8),1000000),C8+1,C8) -> 2 | D9: =가정!$B$34^(C9-1) -> 2.5 | E9: =(B9/10)^가정!$B$36 -> 21.47901 | F9: =IF(C9>C8,(F8+E9)*가정!$B$35,F8+E9) -> 115.14811 | G9: =(1+F9*가정!$B$37)*D9 -> 8.2574056 | H9: =(1+F9*가정!$B$38)*D9^0.6 -> 4.7258991 | I9: =가정!$B$5*가정!$B$7*가정!$B$6^(B9-1)/가정!$B$18 -> 715.09353 | J9: =(가정!$B$12+가정!$B$15*(LOG(가정!$B$9*가정!$B$7*H9*가정!$B$10^B9/(가정!$B$10-1)*(가정!$B$14-1)/가정!$B$13)/LOG(가정!$B$14)))*G9 -> 1709.9858 | K9: =IFERROR(J9/I9,0) -> 2.3912758 | L9: =A9/가정!$B$39 -> 2.6666667 | M9: =IF(K9<1,"미달",IF(K9>4,"과잉","적정")) -> 적정
A10: 9 | B10: =ROUND(가정!$B$32*(A10+1)^가정!$B$33,0) -> 70 | C10: =IF(B10>=IFERROR(INDEX(가정!$B$42:$B$50,C9),1000000),C9+1,C9) -> 2 | D10: =가정!$B$34^(C10-1) -> 2.5 | E10: =(B10/10)^가정!$B$36 -> 22.498671 | F10: =IF(C10>C9,(F9+E10)*가정!$B$35,F9+E10) -> 137.64678 | G10: =(1+F10*가정!$B$37)*D10 -> 9.3823392 | H10: =(1+F10*가정!$B$38)*D10^0.6 -> 5.3107055 | I10: =가정!$B$5*가정!$B$7*가정!$B$6^(B10-1)/가정!$B$18 -> 849.60262 | J10: =(가정!$B$12+가정!$B$15*(LOG(가정!$B$9*가정!$B$7*H10*가정!$B$10^B10/(가정!$B$10-1)*(가정!$B$14-1)/가정!$B$13)/LOG(가정!$B$14)))*G10 -> 2007.843 | K10: =IFERROR(J10/I10,0) -> 2.363273 | L10: =A10/가정!$B$39 -> 3 | M10: =IF(K10<1,"미달",IF(K10>4,"과잉","적정")) -> 적정
A11: 10 | B11: =ROUND(가정!$B$32*(A11+1)^가정!$B$33,0) -> 72 | C11: =IF(B11>=IFERROR(INDEX(가정!$B$42:$B$50,C10),1000000),C10+1,C10) -> 2 | D11: =가정!$B$34^(C11-1) -> 2.5 | E11: =(B11/10)^가정!$B$36 -> 23.535964 | F11: =IF(C11>C10,(F10+E11)*가정!$B$35,F10+E11) -> 161.18275 | G11: =(1+F11*가정!$B$37)*D11 -> 10.559137 | H11: =(1+F11*가정!$B$38)*D11^0.6 -> 5.9224742 | I11: =가정!$B$5*가정!$B$7*가정!$B$6^(B11-1)/가정!$B$18 -> 1009.4129 | J11: =(가정!$B$12+가정!$B$15*(LOG(가정!$B$9*가정!$B$7*H11*가정!$B$10^B11/(가정!$B$10-1)*(가정!$B$14-1)/가정!$B$13)/LOG(가정!$B$14)))*G11 -> 2330.5862 | K11: =IFERROR(J11/I11,0) -> 2.3088532 | L11: =A11/가정!$B$39 -> 3.3333333 | M11: =IF(K11<1,"미달",IF(K11>4,"과잉","적정")) -> 적정
A12: 11 | B12: =ROUND(가정!$B$32*(A12+1)^가정!$B$33,0) -> 74 | C12: =IF(B12>=IFERROR(INDEX(가정!$B$42:$B$50,C11),1000000),C11+1,C11) -> 2 | D12: =가정!$B$34^(C12-1) -> 2.5 | E12: =(B12/10)^가정!$B$36 -> 24.590692 | F12: =IF(C12>C11,(F11+E12)*가정!$B$35,F11+E12) -> 185.77344 | G12: =(1+F12*가정!$B$37)*D12 -> 11.788672 | H12: =(1+F12*가정!$B$38)*D12^0.6 -> 6.5616584 | I12: =가정!$B$5*가정!$B$7*가정!$B$6^(B12-1)/가정!$B$18 -> 1199.2834 | J12: =(가정!$B$12+가정!$B$15*(LOG(가정!$B$9*가정!$B$7*H12*가정!$B$10^B12/(가정!$B$10-1)*(가정!$B$14-1)/가정!$B$13)/LOG(가정!$B$14)))*G12 -> 2679.0869 | K12: =IFERROR(J12/I12,0) -> 2.2339064 | L12: =A12/가정!$B$39 -> 3.6666667 | M12: =IF(K12<1,"미달",IF(K12>4,"과잉","적정")) -> 적정
A13: 12 | B13: =ROUND(가정!$B$32*(A13+1)^가정!$B$33,0) -> 75 | C13: =IF(B13>=IFERROR(INDEX(가정!$B$42:$B$50,C12),1000000),C12+1,C12) -> 2 | D13: =가정!$B$34^(C13-1) -> 2.5 | E13: =(B13/10)^가정!$B$36 -> 25.124534 | F13: =IF(C13>C12,(F12+E13)*가정!$B$35,F12+E13) -> 210.89797 | G13: =(1+F13*가정!$B$37)*D13 -> 13.044899 | H13: =(1+F13*가정!$B$38)*D13^0.6 -> 7.2147187 | I13: =가정!$B$5*가정!$B$7*가정!$B$6^(B13-1)/가정!$B$18 -> 1307.2189 | J13: =(가정!$B$12+가정!$B$15*(LOG(가정!$B$9*가정!$B$7*H13*가정!$B$10^B13/(가정!$B$10-1)*(가정!$B$14-1)/가정!$B$13)/LOG(가정!$B$14)))*G13 -> 3022.314 | K13: =IFERROR(J13/I13,0) -> 2.3120182 | L13: =A13/가정!$B$39 -> 4 | M13: =IF(K13<1,"미달",IF(K13>4,"과잉","적정")) -> 적정
A14: 13 | B14: =ROUND(가정!$B$32*(A14+1)^가정!$B$33,0) -> 77 | C14: =IF(B14>=IFERROR(INDEX(가정!$B$42:$B$50,C13),1000000),C13+1,C13) -> 2 | D14: =가정!$B$34^(C14-1) -> 2.5 | E14: =(B14/10)^가정!$B$36 -> 26.20506 | F14: =IF(C14>C13,(F13+E14)*가정!$B$35,F13+E14) -> 237.10303 | G14: =(1+F14*가정!$B$37)*D14 -> 14.355152 | H14: =(1+F14*가정!$B$38)*D14^0.6 -> 7.8958651 | I14: =가정!$B$5*가정!$B$7*가정!$B$6^(B14-1)/가정!$B$18 -> 1553.1068 | J14: =(가정!$B$12+가정!$B$15*(LOG(가정!$B$9*가정!$B$7*H14*가정!$B$10^B14/(가정!$B$10-1)*(가정!$B$14-1)/가정!$B$13)/LOG(가정!$B$14)))*G14 -> 3415.1276 | K14: =IFERROR(J14/I14,0) -> 2.1989006 | L14: =A14/가정!$B$39 -> 4.3333333 | M14: =IF(K14<1,"미달",IF(K14>4,"과잉","적정")) -> 적정
... A39: 38 | B39: =ROUND(가정!$B$32*(A39+1)^가정!$B$33,0) -> 101 | C39: =IF(B39>=IFERROR(INDEX(가정!$B$42:$B$50,C38),1000000),C38+1,C38) -> 4 | D39: =가정!$B$34^(C39-1) -> 15.625 | E39: =(B39/10)^가정!$B$36 -> 40.449597 | F39: =IF(C39>C38,(F38+E39)*가정!$B$35,F38+E39) -> 191.40776 | G39: =(1+F39*가정!$B$37)*D39 -> 75.439925 | H39: =(1+F39*가정!$B$38)*D39^0.6 -> 20.14319 | I39: =가정!$B$5*가정!$B$7*가정!$B$6^(B39-1)/가정!$B$18 -> 12286.757 | J39: =(가정!$B$12+가정!$B$15*(LOG(가정!$B$9*가정!$B$7*H39*가정!$B$10^B39/(가정!$B$10-1)*(가정!$B$14-1)/가정!$B$13)/LOG(가정!$B$14)))*G39 -> 23283.838 | K39: =IFERROR(J39/I39,0) -> 1.8950352 | L39: =A39/가정!$B$39 -> 12.666667 | M39: =IF(K39<1,"미달",IF(K39>4,"과잉","적정")) -> 적정
A40: 39 | B40: =ROUND(가정!$B$32*(A40+1)^가정!$B$33,0) -> 102 | C40: =IF(B40>=IFERROR(INDEX(가정!$B$42:$B$50,C39),1000000),C39+1,C39) -> 4 | D40: =가정!$B$34^(C40-1) -> 15.625 | E40: =(B40/10)^가정!$B$36 -> 41.092283 | F40: =IF(C40>C39,(F39+E40)*가정!$B$35,F39+E40) -> 232.50004 | G40: =(1+F40*가정!$B$37)*D40 -> 88.281264 | H40: =(1+F40*가정!$B$38)*D40^0.6 -> 23.350519 | I40: =가정!$B$5*가정!$B$7*가정!$B$6^(B40-1)/가정!$B$18 -> 13392.565 | J40: =(가정!$B$12+가정!$B$15*(LOG(가정!$B$9*가정!$B$7*H40*가정!$B$10^B40/(가정!$B$10-1)*(가정!$B$14-1)/가정!$B$13)/LOG(가정!$B$14)))*G40 -> 27761.501 | K40: =IFERROR(J40/I40,0) -> 2.0729039 | L40: =A40/가정!$B$39 -> 13 | M40: =IF(K40<1,"미달",IF(K40>4,"과잉","적정")) -> 적정 | O40: ⚠ 자동 진단 — 파라미터를 바꾼 뒤 반드시 여기를 확인
A41: 40 | B41: =ROUND(가정!$B$32*(A41+1)^가정!$B$33,0) -> 102 | C41: =IF(B41>=IFERROR(INDEX(가정!$B$42:$B$50,C40),1000000),C40+1,C40) -> 4 | D41: =가정!$B$34^(C41-1) -> 15.625 | E41: =(B41/10)^가정!$B$36 -> 41.092283 | F41: =IF(C41>C40,(F40+E41)*가정!$B$35,F40+E41) -> 273.59233 | G41: =(1+F41*가정!$B$37)*D41 -> 101.1226 | H41: =(1+F41*가정!$B$38)*D41^0.6 -> 26.557848 | I41: =가정!$B$5*가정!$B$7*가정!$B$6^(B41-1)/가정!$B$18 -> 13392.565 | J41: =(가정!$B$12+가정!$B$15*(LOG(가정!$B$9*가정!$B$7*H41*가정!$B$10^B41/(가정!$B$10-1)*(가정!$B$14-1)/가정!$B$13)/LOG(가정!$B$14)))*G41 -> 32144.203 | K41: =IFERROR(J41/I41,0) -> 2.4001528 | L41: =A41/가정!$B$39 -> 13.333333 | M41: =IF(K41<1,"미달",IF(K41>4,"과잉","적정")) -> 적정 | O41: 여유 최솟값 | P41: =MIN(K2:K301) -> 1.0193976 | Q41: 1.00 미만이면 진행 불가 구간이 생긴 것
A42: 41 | B42: =ROUND(가정!$B$32*(A42+1)^가정!$B$33,0) -> 103 | C42: =IF(B42>=IFERROR(INDEX(가정!$B$42:$B$50,C41),1000000),C41+1,C41) -> 4 | D42: =가정!$B$34^(C42-1) -> 15.625 | E42: =(B42/10)^가정!$B$36 -> 41.738762 | F42: =IF(C42>C41,(F41+E42)*가정!$B$35,F41+E42) -> 315.33109 | G42: =(1+F42*가정!$B$37)*D42 -> 114.16597 | H42: =(1+F42*가정!$B$38)*D42^0.6 -> 29.815637 | I42: =가정!$B$5*가정!$B$7*가정!$B$6^(B42-1)/가정!$B$18 -> 14597.896 | J42: =(가정!$B$12+가정!$B$15*(LOG(가정!$B$9*가정!$B$7*H42*가정!$B$10^B42/(가정!$B$10-1)*(가정!$B$14-1)/가정!$B$13)/LOG(가정!$B$14)))*G42 -> 36858.596 | K42: =IFERROR(J42/I42,0) -> 2.5249252 | L42: =A42/가정!$B$39 -> 13.666667 | M42: =IF(K42<1,"미달",IF(K42>4,"과잉","적정")) -> 적정 | O42: 여유 최댓값 | P42: =MAX(K2:K301) -> 4.0054533 | Q42: 6 이상이면 너무 쉬워 긴장감이 사라짐
A43: 42 | B43: =ROUND(가정!$B$32*(A43+1)^가정!$B$33,0) -> 104 | C43: =IF(B43>=IFERROR(INDEX(가정!$B$42:$B$50,C42),1000000),C42+1,C42) -> 4 | D43: =가정!$B$34^(C43-1) -> 15.625 | E43: =(B43/10)^가정!$B$36 -> 42.389017 | F43: =IF(C43>C42,(F42+E43)*가정!$B$35,F42+E43) -> 357.72011 | G43: =(1+F43*가정!$B$37)*D43 -> 127.41253 | H43: =(1+F43*가정!$B$38)*D43^0.6 -> 33.124178 | I43: =가정!$B$5*가정!$B$7*가정!$B$6^(B43-1)/가정!$B$18 -> 15911.707 | J43: =(가정!$B$12+가정!$B$15*(LOG(가정!$B$9*가정!$B$7*H43*가정!$B$10^B43/(가정!$B$10-1)*(가정!$B$14-1)/가정!$B$13)/LOG(가정!$B$14)))*G43 -> 41734.112 | K43: =IFERROR(J43/I43,0) -> 2.6228557 | L43: =A43/가정!$B$39 -> 14 | M43: =IF(K43<1,"미달",IF(K43>4,"과잉","적정")) -> 적정 | O43: 미달 회차 수 | P43: =COUNTIF(M2:M301,"미달") -> 0 | Q43: 0이어야 정상
A44: 43 | B44: =ROUND(가정!$B$32*(A44+1)^가정!$B$33,0) -> 104 | C44: =IF(B44>=IFERROR(INDEX(가정!$B$42:$B$50,C43),1000000),C43+1,C43) -> 4 | D44: =가정!$B$34^(C44-1) -> 15.625 | E44: =(B44/10)^가정!$B$36 -> 42.389017 | F44: =IF(C44>C43,(F43+E44)*가정!$B$35,F43+E44) -> 400.10912 | G44: =(1+F44*가정!$B$37)*D44 -> 140.6591 | H44: =(1+F44*가정!$B$38)*D44^0.6 -> 36.43272 | I44: =가정!$B$5*가정!$B$7*가정!$B$6^(B44-1)/가정!$B$18 -> 15911.707 | J44: =(가정!$B$12+가정!$B$15*(LOG(가정!$B$9*가정!$B$7*H44*가정!$B$10^B44/(가정!$B$10-1)*(가정!$B$14-1)/가정!$B$13)/LOG(가정!$B$14)))*G44 -> 46427.529 | K44: =IFERROR(J44/I44,0) -> 2.917822 | L44: =A44/가정!$B$39 -> 14.333333 | M44: =IF(K44<1,"미달",IF(K44>4,"과잉","적정")) -> 적정 | O44: 300회차 최종 티어 | P44: =C301 -> 6 | Q44: 9에 도달하면 콘텐츠 소진 — 게이트를 늘릴 것
A45: 44 | B45: =ROUND(가정!$B$32*(A45+1)^가정!$B$33,0) -> 105 | C45: =IF(B45>=IFERROR(INDEX(가정!$B$42:$B$50,C44),1000000),C44+1,C44) -> 4 | D45: =가정!$B$34^(C45-1) -> 15.625 | E45: =(B45/10)^가정!$B$36 -> 43.043034 | F45: =IF(C45>C44,(F44+E45)*가정!$B$35,F44+E45) -> 443.15216 | G45: =(1+F45*가정!$B$37)*D45 -> 154.11005 | H45: =(1+F45*가정!$B$38)*D45^0.6 -> 39.792309 | I45: =가정!$B$5*가정!$B$7*가정!$B$6^(B45-1)/가정!$B$18 -> 17343.761 | J45: =(가정!$B$12+가정!$B$15*(LOG(가정!$B$9*가정!$B$7*H45*가정!$B$10^B45/(가정!$B$10-1)*(가정!$B$14-1)/가정!$B$13)/LOG(가정!$B$14)))*G45 -> 51522.179 | K45: =IFERROR(J45/I45,0) -> 2.9706463 | L45: =A45/가정!$B$39 -> 14.666667 | M45: =IF(K45<1,"미달",IF(K45>4,"과잉","적정")) -> 적정 | O45: 90일차 도달 웨이브 | P45: =INDEX(B2:B301,MIN(300,ROUND(90*가정!$B$39,0))) -> 170
A46: 45 | B46: =ROUND(가정!$B$32*(A46+1)^가정!$B$33,0) -> 106 | C46: =IF(B46>=IFERROR(INDEX(가정!$B$42:$B$50,C45),1000000),C45+1,C45) -> 4 | D46: =가정!$B$34^(C46-1) -> 15.625 | E46: =(B46/10)^가정!$B$36 -> 43.7008 | F46: =IF(C46>C45,(F45+E46)*가정!$B$35,F45+E46) -> 486.85296 | G46: =(1+F46*가정!$B$37)*D46 -> 167.76655 | H46: =(1+F46*가정!$B$38)*D46^0.6 -> 43.203238 | I46: =가정!$B$5*가정!$B$7*가정!$B$6^(B46-1)/가정!$B$18 -> 18904.699 | J46: =(가정!$B$12+가정!$B$15*(LOG(가정!$B$9*가정!$B$7*H46*가정!$B$10^B46/(가정!$B$10-1)*(가정!$B$14-1)/가정!$B$13)/LOG(가정!$B$14)))*G46 -> 56774.251 | K46: =IFERROR(J46/I46,0) -> 3.0031819 | L46: =A46/가정!$B$39 -> 15 | M46: =IF(K46<1,"미달",IF(K46>4,"과잉","적정")) -> 적정 | O46: 종합 판정 | P46: =IF(AND(MIN(K2:K301)>=1,COUNTIF(M2:M301,"미달")=0,C301<9),"정상","재조정 필요") -> 정상
A47: 46 | B47: =ROUND(가정!$B$32*(A47+1)^가정!$B$33,0) -> 106 | C47: =IF(B47>=IFERROR(INDEX(가정!$B$42:$B$50,C46),1000000),C46+1,C46) -> 4 | D47: =가정!$B$34^(C47-1) -> 15.625 | E47: =(B47/10)^가정!$B$36 -> 43.7008 | F47: =IF(C47>C46,(F46+E47)*가정!$B$35,F46+E47) -> 530.55376 | G47: =(1+F47*가정!$B$37)*D47 -> 181.42305 | H47: =(1+F47*가정!$B$38)*D47^0.6 -> 46.614167 | I47: =가정!$B$5*가정!$B$7*가정!$B$6^(B47-1)/가정!$B$18 -> 18904.699 | J47: =(가정!$B$12+가정!$B$15*(LOG(가정!$B$9*가정!$B$7*H47*가정!$B$10^B47/(가정!$B$10-1)*(가정!$B$14-1)/가정!$B$13)/LOG(가정!$B$14)))*G47 -> 61760.721 | K47: =IFERROR(J47/I47,0) -> 3.2669507 | L47: =A47/가정!$B$39 -> 15.333333 | M47: =IF(K47<1,"미달",IF(K47>4,"과잉","적정")) -> 적정
A48: 47 | B48: =ROUND(가정!$B$32*(A48+1)^가정!$B$33,0) -> 107 | C48: =IF(B48>=IFERROR(INDEX(가정!$B$42:$B$50,C47),1000000),C47+1,C47) -> 4 | D48: =가정!$B$34^(C48-1) -> 15.625 | E48: =(B48/10)^가정!$B$36 -> 44.362299 | F48: =IF(C48>C47,(F47+E48)*가정!$B$35,F47+E48) -> 574.91605 | G48: =(1+F48*가정!$B$37)*D48 -> 195.28627 | H48: =(1+F48*가정!$B$38)*D48^0.6 -> 50.076727 | I48: =가정!$B$5*가정!$B$7*가정!$B$6^(B48-1)/가정!$B$18 -> 20606.122 | J48: =(가정!$B$12+가정!$B$15*(LOG(가정!$B$9*가정!$B$7*H48*가정!$B$10^B48/(가정!$B$10-1)*(가정!$B$14-1)/가정!$B$13)/LOG(가정!$B$14)))*G48 -> 67224.364 | K48: =IFERROR(J48/I48,0) -> 3.2623491 | L48: =A48/가정!$B$39 -> 15.666667 | M48: =IF(K48<1,"미달",IF(K48>4,"과잉","적정")) -> 적정
A49: 48 | B49: =ROUND(가정!$B$32*(A49+1)^가정!$B$33,0) -> 107 | C49: =IF(B49>=IFERROR(INDEX(가정!$B$42:$B$50,C48),1000000),C48+1,C48) -> 4 | D49: =가정!$B$34^(C49-1) -> 15.625 | E49: =(B49/10)^가정!$B$36 -> 44.362299 | F49: =IF(C49>C48,(F48+E49)*가정!$B$35,F48+E49) -> 619.27835 | G49: =(1+F49*가정!$B$37)*D49 -> 209.14949 | H49: =(1+F49*가정!$B$38)*D49^0.6 -> 53.539287 | I49: =가정!$B$5*가정!$B$7*가정!$B$6^(B49-1)/가정!$B$18 -> 20606.122 | J49: =(가정!$B$12+가정!$B$15*(LOG(가정!$B$9*가정!$B$7*H49*가정!$B$10^B49/(가정!$B$10-1)*(가정!$B$14-1)/가정!$B$13)/LOG(가정!$B$14)))*G49 -> 72366.738 | K49: =IFERROR(J49/I49,0) -> 3.5119047 | L49: =A49/가정!$B$39 -> 16 | M49: =IF(K49<1,"미달",IF(K49>4,"과잉","적정")) -> 적정
A50: 49 | B50: =ROUND(가정!$B$32*(A50+1)^가정!$B$33,0) -> 108 | C50: =IF(B50>=IFERROR(INDEX(가정!$B$42:$B$50,C49),1000000),C49+1,C49) -> 4 | D50: =가정!$B$34^(C50-1) -> 15.625 | E50: =(B50/10)^가정!$B$36 -> 45.027518 | F50: =IF(C50>C49,(F49+E50)*가정!$B$35,F49+E50) -> 664.30587 | G50: =(1+F50*가정!$B$37)*D50 -> 223.22058 | H50: =(1+F50*가정!$B$38)*D50^0.6 -> 57.053769 | I50: =가정!$B$5*가정!$B$7*가정!$B$6^(B50-1)/가정!$B$18 -> 22460.673 | J50: =(가정!$B$12+가정!$B$15*(LOG(가정!$B$9*가정!$B$7*H50*가정!$B$10^B50/(가정!$B$10-1)*(가정!$B$14-1)/가정!$B$13)/LOG(가정!$B$14)))*G50 -> 78038.437 | K50: =IFERROR(J50/I50,0) -> 3.4744478 | L50: =A50/가정!$B$39 -> 16.333333 | M50: =IF(K50<1,"미달",IF(K50>4,"과잉","적정")) -> 적정
A51: 50 | B51: =ROUND(가정!$B$32*(A51+1)^가정!$B$33,0) -> 109 | C51: =IF(B51>=IFERROR(INDEX(가정!$B$42:$B$50,C50),1000000),C50+1,C50) -> 4 | D51: =가정!$B$34^(C51-1) -> 15.625 | E51: =(B51/10)^가정!$B$36 -> 45.696443 | F51: =IF(C51>C50,(F50+E51)*가정!$B$35,F50+E51) -> 710.00231 | G51: =(1+F51*가정!$B$37)*D51 -> 237.50072 | H51: =(1+F51*가정!$B$38)*D51^0.6 -> 60.620461 | I51: =가정!$B$5*가정!$B$7*가정!$B$6^(B51-1)/가정!$B$18 -> 24482.134 | J51: =(가정!$B$12+가정!$B$15*(LOG(가정!$B$9*가정!$B$7*H51*가정!$B$10^B51/(가정!$B$10-1)*(가정!$B$14-1)/가정!$B$13)/LOG(가정!$B$14)))*G51 -> 83866.725 | K51: =IFERROR(J51/I51,0) -> 3.4256298 | L51: =A51/가정!$B$39 -> 16.666667 | M51: =IF(K51<1,"미달",IF(K51>4,"과잉","적정")) -> 적정
A52: 51 | B52: =ROUND(가정!$B$32*(A52+1)^가정!$B$33,0) -> 109 | C52: =IF(B52>=IFERROR(INDEX(가정!$B$42:$B$50,C51),1000000),C51+1,C51) -> 4 | D52: =가정!$B$34^(C52-1) -> 15.625 | E52: =(B52/10)^가정!$B$36 -> 45.696443 | F52: =IF(C52>C51,(F51+E52)*가정!$B$35,F51+E52) -> 755.69876 | G52: =(1+F52*가정!$B$37)*D52 -> 251.78086 | H52: =(1+F52*가정!$B$38)*D52^0.6 -> 64.187154 | I52: =가정!$B$5*가정!$B$7*가정!$B$6^(B52-1)/가정!$B$18 -> 24482.134 | J52: =(가정!$B$12+가정!$B$15*(LOG(가정!$B$9*가정!$B$7*H52*가정!$B$10^B52/(가정!$B$10-1)*(가정!$B$14-1)/가정!$B$13)/LOG(가정!$B$14)))*G52 -> 89290.402 | K52: =IFERROR(J52/I52,0) -> 3.6471659 | L52: =A52/가정!$B$39 -> 17 | M52: =IF(K52<1,"미달",IF(K52>4,"과잉","적정")) -> 적정
A53: 52 | B53: =ROUND(가정!$B$32*(A53+1)^가정!$B$33,0) -> 110 | C53: =IF(B53>=IFERROR(INDEX(가정!$B$42:$B$50,C52),1000000),C52+1,C52) -> 4 | D53: =가정!$B$34^(C53-1) -> 15.625 | E53: =(B53/10)^가정!$B$36 -> 46.36906 | F53: =IF(C53>C52,(F52+E53)*가정!$B$35,F52+E53) -> 802.06782 | G53: =(1+F53*가정!$B$37)*D53 -> 266.27119 | H53: =(1+F53*가정!$B$38)*D53^0.6 -> 67.806345 | I53: =가정!$B$5*가정!$B$7*가정!$B$6^(B53-1)/가정!$B$18 -> 26685.526 | J53: =(가정!$B$12+가정!$B$15*(LOG(가정!$B$9*가정!$B$7*H53*가정!$B$10^B53/(가정!$B$10-1)*(가정!$B$14-1)/가정!$B$13)/LOG(가정!$B$14)))*G53 -> 95325.586 | K53: =IFERROR(J53/I53,0) -> 3.5721832 | L53: =A53/가정!$B$39 -> 17.333333 | M53: =IF(K53<1,"미달",IF(K53>4,"과잉","적정")) -> 적정
A54: 53 | B54: =ROUND(가정!$B$32*(A54+1)^가정!$B$33,0) -> 110 | C54: =IF(B54>=IFERROR(INDEX(가정!$B$42:$B$50,C53),1000000),C53+1,C53) -> 4 | D54: =가정!$B$34^(C54-1) -> 15.625 | E54: =(B54/10)^가정!$B$36 -> 46.36906 | F54: =IF(C54>C53,(F53+E54)*가정!$B$35,F53+E54) -> 848.43688 | G54: =(1+F54*가정!$B$37)*D54 -> 280.76152 | H54: =(1+F54*가정!$B$38)*D54^0.6 -> 71.425537 | I54: =가정!$B$5*가정!$B$7*가정!$B$6^(B54-1)/가정!$B$18 -> 26685.526 | J54: =(가정!$B$12+가정!$B$15*(LOG(가정!$B$9*가정!$B$7*H54*가정!$B$10^B54/(가정!$B$10-1)*(가정!$B$14-1)/가정!$B$13)/LOG(가정!$B$14)))*G54 -> 100899.62 | K54: =IFERROR(J54/I54,0) -> 3.7810619 | L54: =A54/가정!$B$39 -> 17.666667 | M54: =IF(K54<1,"미달",IF(K54>4,"과잉","적정")) -> 적정
A55: 54 | B55: =ROUND(가정!$B$32*(A55+1)^가정!$B$33,0) -> 111 | C55: =IF(B55>=IFERROR(INDEX(가정!$B$42:$B$50,C54),1000000),C54+1,C54) -> 4 | D55: =가정!$B$34^(C55-1) -> 15.625 | E55: =(B55/10)^가정!$B$36 -> 47.045357 | F55: =IF(C55>C54,(F54+E55)*가정!$B$35,F54+E55) -> 895.48224 | G55: =(1+F55*가정!$B$37)*D55 -> 295.4632 | H55: =(1+F55*가정!$B$38)*D55^0.6 -> 75.097514 | I55: =가정!$B$5*가정!$B$7*가정!$B$6^(B55-1)/가정!$B$18 -> 29087.223 | J55: =(가정!$B$12+가정!$B$15*(LOG(가정!$B$9*가정!$B$7*H55*가정!$B$10^B55/(가정!$B$10-1)*(가정!$B$14-1)/가정!$B$13)/LOG(가정!$B$14)))*G55 -> 107140.84 | K55: =IFERROR(J55/I55,0) -> 3.6834331 | L55: =A55/가정!$B$39 -> 18 | M55: =IF(K55<1,"미달",IF(K55>4,"과잉","적정")) -> 적정
A56: 55 | B56: =ROUND(가정!$B$32*(A56+1)^가정!$B$33,0) -> 111 | C56: =IF(B56>=IFERROR(INDEX(가정!$B$42:$B$50,C55),1000000),C55+1,C55) -> 4 | D56: =가정!$B$34^(C56-1) -> 15.625 | E56: =(B56/10)^가정!$B$36 -> 47.045357 | F56: =IF(C56>C55,(F55+E56)*가정!$B$35,F55+E56) -> 942.52759 | G56: =(1+F56*가정!$B$37)*D56 -> 310.16487 | H56: =(1+F56*가정!$B$38)*D56^0.6 -> 78.769492 | I56: =가정!$B$5*가정!$B$7*가정!$B$6^(B56-1)/가정!$B$18 -> 29087.223 | J56: =(가정!$B$12+가정!$B$15*(LOG(가정!$B$9*가정!$B$7*H56*가정!$B$10^B56/(가정!$B$10-1)*(가정!$B$14-1)/가정!$B$13)/LOG(가정!$B$14)))*G56 -> 112863.92 | K56: =IFERROR(J56/I56,0) -> 3.8801889 | L56: =A56/가정!$B$39 -> 18.333333 | M56: =IF(K56<1,"미달",IF(K56>4,"과잉","적정")) -> 적정
A57: 56 | B57: =ROUND(가정!$B$32*(A57+1)^가정!$B$33,0) -> 112 | C57: =IF(B57>=IFERROR(INDEX(가정!$B$42:$B$50,C56),1000000),C56+1,C56) -> 4 | D57: =가정!$B$34^(C57-1) -> 15.625 | E57: =(B57/10)^가정!$B$36 -> 47.725319 | F57: =IF(C57>C56,(F56+E57)*가정!$B$35,F56+E57) -> 990.25291 | G57: =(1+F57*가정!$B$37)*D57 -> 325.07903 | H57: =(1+F57*가정!$B$38)*D57^0.6 -> 82.494542 | I57: =가정!$B$5*가정!$B$7*가정!$B$6^(B57-1)/가정!$B$18 -> 31705.073 | J57: =(가정!$B$12+가정!$B$15*(LOG(가정!$B$9*가정!$B$7*H57*가정!$B$10^B57/(가정!$B$10-1)*(가정!$B$14-1)/가정!$B$13)/LOG(가정!$B$14)))*G57 -> 119310.91 | K57: =IFERROR(J57/I57,0) -> 3.7631489 | L57: =A57/가정!$B$39 -> 18.666667 | M57: =IF(K57<1,"미달",IF(K57>4,"과잉","적정")) -> 적정
A58: 57 | B58: =ROUND(가정!$B$32*(A58+1)^가정!$B$33,0) -> 112 | C58: =IF(B58>=IFERROR(INDEX(가정!$B$42:$B$50,C57),1000000),C57+1,C57) -> 4 | D58: =가정!$B$34^(C58-1) -> 15.625 | E58: =(B58/10)^가정!$B$36 -> 47.725319 | F58: =IF(C58>C57,(F57+E58)*가정!$B$35,F57+E58) -> 1037.9782 | G58: =(1+F58*가정!$B$37)*D58 -> 339.9932 | H58: =(1+F58*가정!$B$38)*D58^0.6 -> 86.219592 | I58: =가정!$B$5*가정!$B$7*가정!$B$6^(B58-1)/가정!$B$18 -> 31705.073 | J58: =(가정!$B$12+가정!$B$15*(LOG(가정!$B$9*가정!$B$7*H58*가정!$B$10^B58/(가정!$B$10-1)*(가정!$B$14-1)/가정!$B$13)/LOG(가정!$B$14)))*G58 -> 125182.22 | K58: =IFERROR(J58/I58,0) -> 3.9483341 | L58: =A58/가정!$B$39 -> 19 | M58: =IF(K58<1,"미달",IF(K58>4,"과잉","적정")) -> 적정
... A301: 300 | B301: =ROUND(가정!$B$32*(A301+1)^가정!$B$33,0) -> 175 | C301: =IF(B301>=IFERROR(INDEX(가정!$B$42:$B$50,C300),1000000),C300+1,C300) -> 6 | D301: =가정!$B$34^(C301-1) -> 97.65625 | E301: =(B301/10)^가정!$B$36 -> 97.467736 | F301: =IF(C301>C300,(F300+E301)*가정!$B$35,F300+E301) -> 12502.435 | G301: =(1+F301*가정!$B$37)*D301 -> 24516.474 | H301: =(1+F301*가정!$B$38)*D301^0.6 -> 2945.8832 | I301: =가정!$B$5*가정!$B$7*가정!$B$6^(B301-1)/가정!$B$18 -> 7227666.9 | J301: =(가정!$B$12+가정!$B$15*(LOG(가정!$B$9*가정!$B$7*H301*가정!$B$10^B301/(가정!$B$10-1)*(가정!$B$14-1)/가정!$B$13)/LOG(가정!$B$14)))*G301 -> 14275433 | K301: =IFERROR(J301/I301,0) -> 1.9751094 | L301: =A301/가정!$B$39 -> 100 | M301: =IF(K301<1,"미달",IF(K301>4,"과잉","적정")) -> 적정

Sheet 90일커브
A1: 90일 리텐션 커브 — 마일스톤
A2: 환생메타 시트를 일자 기준으로 요약합니다. 이 표가 라이브 이벤트 배치의 기준이 됩니다.
A4: 일차 | B4: 누적 회차 | C4: 도달 웨이브 | D4: 티어 | E4: 공격 배수 | F4: 직전 구간 성장
A5: 1 | B5: =MIN(300,ROUND(A5*가정!$B$39,0)) -> 3 | C5: =INDEX(환생메타!$B$2:$B$301,B5) -> 55 | D5: =INDEX(환생메타!$C$2:$C$301,B5) -> 2 | E5: =INDEX(환생메타!$G$2:$G$301,B5) -> 3.4496847 | F5: =""
A6: 2 | B6: =MIN(300,ROUND(A6*가정!$B$39,0)) -> 6 | C6: =INDEX(환생메타!$B$2:$B$301,B6) -> 64 | D6: =INDEX(환생메타!$C$2:$C$301,B6) -> 2 | E6: =INDEX(환생메타!$G$2:$G$301,B6) -> 6.1595958 | F6: =C6-C5 -> 9
A7: 3 | B7: =MIN(300,ROUND(A7*가정!$B$39,0)) -> 9 | C7: =INDEX(환생메타!$B$2:$B$301,B7) -> 70 | D7: =INDEX(환생메타!$C$2:$C$301,B7) -> 2 | E7: =INDEX(환생메타!$G$2:$G$301,B7) -> 9.3823392 | F7: =C7-C6 -> 6
A8: 5 | B8: =MIN(300,ROUND(A8*가정!$B$39,0)) -> 15 | C8: =INDEX(환생메타!$B$2:$B$301,B8) -> 79 | D8: =INDEX(환생메타!$C$2:$C$301,B8) -> 2 | E8: =INDEX(환생메타!$G$2:$G$301,B8) -> 17.057865 | F8: =C8-C7 -> 9
A9: 7 | B9: =MIN(300,ROUND(A9*가정!$B$39,0)) -> 21 | C9: =INDEX(환생메타!$B$2:$B$301,B9) -> 87 | D9: =INDEX(환생메타!$C$2:$C$301,B9) -> 3 | E9: =INDEX(환생메타!$G$2:$G$301,B9) -> 31.214689 | F9: =C9-C8 -> 8
A10: 10 | B10: =MIN(300,ROUND(A10*가정!$B$39,0)) -> 30 | C10: =INDEX(환생메타!$B$2:$B$301,B10) -> 95 | D10: =INDEX(환생메타!$C$2:$C$301,B10) -> 3 | E10: =INDEX(환생메타!$G$2:$G$301,B10) -> 70.040556 | F10: =C10-C9 -> 8
A11: 14 | B11: =MIN(300,ROUND(A11*가정!$B$39,0)) -> 42 | C11: =INDEX(환생메타!$B$2:$B$301,B11) -> 104 | D11: =INDEX(환생메타!$C$2:$C$301,B11) -> 4 | E11: =INDEX(환생메타!$G$2:$G$301,B11) -> 127.41253 | F11: =C11-C10 -> 9
A12: 21 | B12: =MIN(300,ROUND(A12*가정!$B$39,0)) -> 63 | C12: =INDEX(환생메타!$B$2:$B$301,B12) -> 115 | D12: =INDEX(환생메타!$C$2:$C$301,B12) -> 4 | E12: =INDEX(환생메타!$G$2:$G$301,B12) -> 432.05081 | F12: =C12-C11 -> 11
A13: 30 | B13: =MIN(300,ROUND(A13*가정!$B$39,0)) -> 90 | C13: =INDEX(환생메타!$B$2:$B$301,B13) -> 127 | D13: =INDEX(환생메타!$C$2:$C$301,B13) -> 5 | E13: =INDEX(환생메타!$G$2:$G$301,B13) -> 596.61551 | F13: =C13-C12 -> 12
A14: 45 | B14: =MIN(300,ROUND(A14*가정!$B$39,0)) -> 135 | C14: =INDEX(환생메타!$B$2:$B$301,B14) -> 141 | D14: =INDEX(환생메타!$C$2:$C$301,B14) -> 5 | E14: =INDEX(환생메타!$G$2:$G$301,B14) -> 2847.9709 | F14: =C14-C13 -> 14
A15: 60 | B15: =MIN(300,ROUND(A15*가정!$B$39,0)) -> 180 | C15: =INDEX(환생메타!$B$2:$B$301,B15) -> 153 | D15: =INDEX(환생메타!$C$2:$C$301,B15) -> 6 | E15: =INDEX(환생메타!$G$2:$G$301,B15) -> 3792.1058 | F15: =C15-C14 -> 12
A16: 75 | B16: =MIN(300,ROUND(A16*가정!$B$39,0)) -> 225 | C16: =INDEX(환생메타!$B$2:$B$301,B16) -> 162 | D16: =INDEX(환생메타!$C$2:$C$301,B16) -> 6 | E16: =INDEX(환생메타!$G$2:$G$301,B16) -> 11034.75 | F16: =C16-C15 -> 9
A17: 90 | B17: =MIN(300,ROUND(A17*가정!$B$39,0)) -> 270 | C17: =INDEX(환생메타!$B$2:$B$301,B17) -> 170 | D17: =INDEX(환생메타!$C$2:$C$301,B17) -> 6 | E17: =INDEX(환생메타!$G$2:$G$301,B17) -> 18926.621 | F17: =C17-C16 -> 8
A19: 읽는 법
A20: · '직전 구간 성장'이 0에 가까워지는 지점이 이탈 위험 구간입니다. 여기에 이벤트를 배치하세요.
A21: · 티어가 올라가는 날이 유저에게 가장 큰 사건입니다. 연출과 보상을 몰아주세요.
A22: · 90일차에도 다음 티어 게이트가 남아 있어야 합니다. 남지 않으면 지수를 낮추세요.
A23: · 한국·일본은 2차 시장입니다. 조기 과금으로 이 커브가 압축되지 않도록 성장은 팔지 마세요.

Sheet 오프라인보상
A1: 오프라인 보상 (4층) — 우리 게임의 차별화 핵심
A2: 설계 원칙: 오프라인은 코인과 젬만 준다. 코어는 절대 주지 않는다.
A3: 코어를 주면 90일 커브가 즉시 붕괴합니다. 이 한 줄이 이 시트의 전부입니다.
A5: 파라미터
A6: 기본 누적 상한 (시간) | B6: 4 | C6: 이 시간이 지나면 더 안 쌓임 → 하루 3회 복귀를 유도
A7: 업그레이드 최대 상한 (시간) | B7: 12 | C7: 수면 보호용. 코어가 아니라 젬으로 개방
A8: 최대 보상 비율 (직전 런 대비) | B8: 0.3 | C8: 핵심 레버. 40%를 넘기면 액티브 플레이가 죽음
A9: 광고 시청 배수 | B9: 2 | C9: 오프라인 화면 = 접속마다 100% 뜨는 리워드 광고 자리
A10: 젬 지급 (시간당) | B10: 25 | C10: 연구소 가속용. 성장 자체는 아님
A11: 분석 기준 회차 | B11: 90 | C11: 아래 표를 어느 시점 기준으로 볼지
A13: 기준 시점 계산
A14: 도달 웨이브 | B14: =ROUND(가정!$B$32*(B11+1)^가정!$B$33,0) -> 127
A15: 런 1회 총 코인 | B15: =가정!$B$9*가정!$B$7*(가정!$B$10^B14-1)/(가정!$B$10-1) -> 2598957.2 | C15: 이 값이 오프라인 보상의 기준선
A17: 자리비움 시간별 보상
A18: 자리비움(h) | B18: 인정 시간(h) | C18: 보상 비율 | D18: 시작 웨이브 | E18: 광고 시 비율 | F18: 광고 시 시작 웨이브 | G18: 젬
A19: 0.5 | B19: =MIN(A19,$B$7) -> 0.5 | C19: =MIN(A19,$B$6)/$B$6*$B$8 -> 0.0375 | D19: =ROUND(LOG(C19*$B$15*(가정!$B$10-1)/(가정!$B$9*가정!$B$7)+1)/LOG(가정!$B$10),0) -> 82 | E19: =MIN(C19*$B$9,0.8) -> 0.075 | F19: =ROUND(LOG(E19*$B$15*(가정!$B$10-1)/(가정!$B$9*가정!$B$7)+1)/LOG(가정!$B$10),0) -> 91 | G19: =B19*$B$10 -> 12.5
A20: 1 | B20: =MIN(A20,$B$7) -> 1 | C20: =MIN(A20,$B$6)/$B$6*$B$8 -> 0.075 | D20: =ROUND(LOG(C20*$B$15*(가정!$B$10-1)/(가정!$B$9*가정!$B$7)+1)/LOG(가정!$B$10),0) -> 91 | E20: =MIN(C20*$B$9,0.8) -> 0.15 | F20: =ROUND(LOG(E20*$B$15*(가정!$B$10-1)/(가정!$B$9*가정!$B$7)+1)/LOG(가정!$B$10),0) -> 101 | G20: =B20*$B$10 -> 25
A21: 2 | B21: =MIN(A21,$B$7) -> 2 | C21: =MIN(A21,$B$6)/$B$6*$B$8 -> 0.15 | D21: =ROUND(LOG(C21*$B$15*(가정!$B$10-1)/(가정!$B$9*가정!$B$7)+1)/LOG(가정!$B$10),0) -> 101 | E21: =MIN(C21*$B$9,0.8) -> 0.3 | F21: =ROUND(LOG(E21*$B$15*(가정!$B$10-1)/(가정!$B$9*가정!$B$7)+1)/LOG(가정!$B$10),0) -> 110 | G21: =B21*$B$10 -> 50
A22: 3 | B22: =MIN(A22,$B$7) -> 3 | C22: =MIN(A22,$B$6)/$B$6*$B$8 -> 0.225 | D22: =ROUND(LOG(C22*$B$15*(가정!$B$10-1)/(가정!$B$9*가정!$B$7)+1)/LOG(가정!$B$10),0) -> 106 | E22: =MIN(C22*$B$9,0.8) -> 0.45 | F22: =ROUND(LOG(E22*$B$15*(가정!$B$10-1)/(가정!$B$9*가정!$B$7)+1)/LOG(가정!$B$10),0) -> 116 | G22: =B22*$B$10 -> 75
A23: 4 | B23: =MIN(A23,$B$7) -> 4 | C23: =MIN(A23,$B$6)/$B$6*$B$8 -> 0.3 | D23: =ROUND(LOG(C23*$B$15*(가정!$B$10-1)/(가정!$B$9*가정!$B$7)+1)/LOG(가정!$B$10),0) -> 110 | E23: =MIN(C23*$B$9,0.8) -> 0.6 | F23: =ROUND(LOG(E23*$B$15*(가정!$B$10-1)/(가정!$B$9*가정!$B$7)+1)/LOG(가정!$B$10),0) -> 120 | G23: =B23*$B$10 -> 100
A24: 6 | B24: =MIN(A24,$B$7) -> 6 | C24: =MIN(A24,$B$6)/$B$6*$B$8 -> 0.3 | D24: =ROUND(LOG(C24*$B$15*(가정!$B$10-1)/(가정!$B$9*가정!$B$7)+1)/LOG(가정!$B$10),0) -> 110 | E24: =MIN(C24*$B$9,0.8) -> 0.6 | F24: =ROUND(LOG(E24*$B$15*(가정!$B$10-1)/(가정!$B$9*가정!$B$7)+1)/LOG(가정!$B$10),0) -> 120 | G24: =B24*$B$10 -> 150
A25: 8 | B25: =MIN(A25,$B$7) -> 8 | C25: =MIN(A25,$B$6)/$B$6*$B$8 -> 0.3 | D25: =ROUND(LOG(C25*$B$15*(가정!$B$10-1)/(가정!$B$9*가정!$B$7)+1)/LOG(가정!$B$10),0) -> 110 | E25: =MIN(C25*$B$9,0.8) -> 0.6 | F25: =ROUND(LOG(E25*$B$15*(가정!$B$10-1)/(가정!$B$9*가정!$B$7)+1)/LOG(가정!$B$10),0) -> 120 | G25: =B25*$B$10 -> 200
A26: 10 | B26: =MIN(A26,$B$7) -> 10 | C26: =MIN(A26,$B$6)/$B$6*$B$8 -> 0.3 | D26: =ROUND(LOG(C26*$B$15*(가정!$B$10-1)/(가정!$B$9*가정!$B$7)+1)/LOG(가정!$B$10),0) -> 110 | E26: =MIN(C26*$B$9,0.8) -> 0.6 | F26: =ROUND(LOG(E26*$B$15*(가정!$B$10-1)/(가정!$B$9*가정!$B$7)+1)/LOG(가정!$B$10),0) -> 120 | G26: =B26*$B$10 -> 250
A27: 12 | B27: =MIN(A27,$B$7) -> 12 | C27: =MIN(A27,$B$6)/$B$6*$B$8 -> 0.3 | D27: =ROUND(LOG(C27*$B$15*(가정!$B$10-1)/(가정!$B$9*가정!$B$7)+1)/LOG(가정!$B$10),0) -> 110 | E27: =MIN(C27*$B$9,0.8) -> 0.6 | F27: =ROUND(LOG(E27*$B$15*(가정!$B$10-1)/(가정!$B$9*가정!$B$7)+1)/LOG(가정!$B$10),0) -> 120 | G27: =B27*$B$10 -> 300
A28: 16 | B28: =MIN(A28,$B$7) -> 12 | C28: =MIN(A28,$B$6)/$B$6*$B$8 -> 0.3 | D28: =ROUND(LOG(C28*$B$15*(가정!$B$10-1)/(가정!$B$9*가정!$B$7)+1)/LOG(가정!$B$10),0) -> 110 | E28: =MIN(C28*$B$9,0.8) -> 0.6 | F28: =ROUND(LOG(E28*$B$15*(가정!$B$10-1)/(가정!$B$9*가정!$B$7)+1)/LOG(가정!$B$10),0) -> 120 | G28: =B28*$B$10 -> 300
A29: 24 | B29: =MIN(A29,$B$7) -> 12 | C29: =MIN(A29,$B$6)/$B$6*$B$8 -> 0.3 | D29: =ROUND(LOG(C29*$B$15*(가정!$B$10-1)/(가정!$B$9*가정!$B$7)+1)/LOG(가정!$B$10),0) -> 110 | E29: =MIN(C29*$B$9,0.8) -> 0.6 | F29: =ROUND(LOG(E29*$B$15*(가정!$B$10-1)/(가정!$B$9*가정!$B$7)+1)/LOG(가정!$B$10),0) -> 120 | G29: =B29*$B$10 -> 300
A32: 복귀 유도 · 광고 노출
A33: 손실 없는 하루 복귀 횟수 | B33: =24/B6 -> 6 | C33: 상한 4h면 하루 6회. 세션 목표와 직결
A34: 오프라인 화면 광고 시청률 | B34: 0.6 | C34: 보상 2배는 강한 유인이라 높게 잡아도 됨
A35: 오프라인發 일일 광고 노출 | B35: =B33*B34 -> 3.6 | C35: 수익모델 시트의 리워드 노출 중 이만큼이 여기서 나옴
A36: 수익모델 총 리워드 노출 대비 | B36: =IFERROR(B35/(수익모델!B5*수익모델!B6),0) -> 0.5 | C36: 50% 안팎이면 건강. 100%에 가까우면 다른 광고 자리가 없다는 뜻
A38: 커브 무결성 체크리스트
A39: □ 오프라인 보상에 코어(환생 화폐)가 포함되어 있지 않은가
A40: □ 보상 비율이 40%를 넘지 않는가 — 넘으면 액티브 플레이 유인이 사라짐
A41: □ 상한 시간을 코어가 아니라 젬으로 열게 되어 있는가
A42: □ 광고 배수 적용 후에도 시작 웨이브가 직전 도달 웨이브를 넘지 않는가
A43: □ 앱을 완전히 종료해도 보상이 누적되는가 (The Tower의 최대 약점)
A45: 네 번째 항목이 깨지면 유저는 '플레이 없이 진행되는 게임'을 하게 됩니다. 반드시 검증하세요.
